BIRDEYE_API_KEY not set. Falling back to on-chain scanning by default
MPS support detected but PYTORCH_ENABLE_MPS_FALLBACK is not set to '1'. Export PYTORCH_ENABLE_MPS_FALLBACK=1 to enable CPU fallback for unsupported ops.
INFO:websockets.server:server listening on 127.0.0.1:8872
INFO:solhunter_zero.scanner_common:No BirdEye API key set, scanning on-chain
WARNING:solhunter_zero.data_sync:periodic sync failed: unhandled errors in a TaskGroup (1 sub-exception)
INFO:websockets.server:connection open
INFO:websockets.server:connection closed
WARNING:root:Invalid websocket URL configuration; falling back to ws://127.0.0.1:8769
Using keypair: default
Traceback (most recent call last):
  File "/Users/sfredx/Documents/Python/Solsniper-zero-main/solhunter_zero/event_bus.py", line 1366, in start_ws_server
    _ws_server = await websockets.serve(
                 ^^^^^^^^^^^^^^^^^^^^^^^
    ...<6 lines>...
    )
    ^
  File "/Users/sfredx/Documents/Python/Solsniper-zero-main/.venv/lib/python3.13/site-packages/websockets/legacy/server.py", line 1116, in __await_impl__
    server = await self._create_server()
             ^^^^^^^^^^^^^^^^^^^^^^^^^^^
  File "/opt/homebrew/Cellar/python@3.13/3.13.6/Frameworks/Python.framework/Versions/3.13/lib/python3.13/asyncio/base_events.py", line 1630, in create_server
    raise OSError(err.errno, msg) from None
OSError: [Errno 48] error while attempting to bind on address ('127.0.0.1', 8769): [errno 48] address already in use

During handling of the above exception, another exception occurred:

Traceback (most recent call last):
  File "/Users/sfredx/Documents/Python/Solsniper-zero-main/scripts/start_all.py", line 360, in <module>
    autopilot.main()
    ~~~~~~~~~~~~~~^^
  File "/Users/sfredx/Documents/Python/Solsniper-zero-main/solhunter_zero/autopilot.py", line 201, in main
    initialize_event_bus()
    ~~~~~~~~~~~~~~~~~~~~^^
  File "/Users/sfredx/Documents/Python/Solsniper-zero-main/solhunter_zero/config.py", line 654, in initialize_event_bus
    _event_bus.initialize_event_bus()
    ~~~~~~~~~~~~~~~~~~~~~~~~~~~~~~~^^
  File "/Users/sfredx/Documents/Python/Solsniper-zero-main/solhunter_zero/event_bus.py", line 1821, in initialize_event_bus
    _reload_bus(None)
    ~~~~~~~~~~~^^^^^^
  File "/Users/sfredx/Documents/Python/Solsniper-zero-main/solhunter_zero/event_bus.py", line 1674, in _reload_bus
    asyncio.run(_reconnect())
    ~~~~~~~~~~~^^^^^^^^^^^^^^
  File "/opt/homebrew/Cellar/python@3.13/3.13.6/Frameworks/Python.framework/Versions/3.13/lib/python3.13/asyncio/runners.py", line 195, in run
    return runner.run(main)
           ~~~~~~~~~~^^^^^^
  File "/opt/homebrew/Cellar/python@3.13/3.13.6/Frameworks/Python.framework/Versions/3.13/lib/python3.13/asyncio/runners.py", line 118, in run
    return self._loop.run_until_complete(task)
           ~~~~~~~~~~~~~~~~~~~~~~~~~~~~~^^^^^^
  File "/opt/homebrew/Cellar/python@3.13/3.13.6/Frameworks/Python.framework/Versions/3.13/lib/python3.13/asyncio/base_events.py", line 725, in run_until_complete
    return future.result()
           ~~~~~~~~~~~~~^^
  File "/Users/sfredx/Documents/Python/Solsniper-zero-main/solhunter_zero/event_bus.py", line 1651, in _reconnect
    await start_ws_server(host, port)
  File "/Users/sfredx/Documents/Python/Solsniper-zero-main/solhunter_zero/event_bus.py", line 1378, in start_ws_server
    await _flush_task
  File "/Users/sfredx/Documents/Python/Solsniper-zero-main/solhunter_zero/event_bus.py", line 1024, in _flush_outgoing
    msg = await q.get()
          ^^^^^^^^^^^^^
  File "/opt/homebrew/Cellar/python@3.13/3.13.6/Frameworks/Python.framework/Versions/3.13/lib/python3.13/asyncio/queues.py", line 186, in get
    await getter
asyncio.exceptions.CancelledError
